Workbook

Sheet Executive Summary
A1: Malaysia Motorcycle Market & Service Analysis
A2: Deep market taxonomy, 2026 model catalogue and service-ecosystem analysis. Snapshot date: 18 Aug 2026.
A4: How to use this workbook
A5: Use Motorcycle Taxonomy to understand market types; Malaysia Model Catalogue for brand/model evidence and status; Brand & Distributor Map for channel structure; Market Signals for registration/service-network metrics; Service Taxonomy and Service Provider Landscape for workshop/service demand; Bike-Service Matrix for relative service intensity; Sources & Methodology for audit trail and caveats.
A8: June 2026 registrations | D8: June 2026 EV share | G8: Cumulative motorcycles since 2000 | J8: Yamaha YQS locations
A9: ='Market Signals'!B5 | D9: ='Market Signals'!B22 | G9: ='Market Signals'!B8 | J9: ='Market Signals'!B16
A10: units | Official JPJ/data.gov.my | D10: % | Derived from official monthly registrations | G10: units | Official JPJ/data.gov.my | J10: locations | OEM states 260+
A12: MODENAS Service Plus | D12: Model / family records | G12: Service items mapped | J12: Service provider archetypes
A13: ='Market Signals'!B17 | D13: =COUNTA('Malaysia Model Catalogue'!B5:B331) | G13: =COUNTA('Service Taxonomy'!B5:B68) | J13: =COUNTA('Service Provider Landscape'!A5:A23)
A14: locations | Official listing snapshot | D14: records | Research catalogue; not sales volume | G14: items | Across mechanical, roadside, claims and EV | J14: records | Representative landscape
A18: Market Structure - Catalogue Records by Type | G18: Key Analytical Findings
A19: Type | B19: Record Count | C19: Interpretation | G19: 1 | H19: Commuter motorcycles remain the service-volume engine. Underbones and scooters generate frequent oil, tyre, brake, chain or CVT visits.
A20: Underbone / commuter moped | B20: =COUNTIF('Malaysia Model Catalogue'!$C$5:$C$331,A20) | C20: Catalogue breadth only - not sales share | G20: 2 | H20: Scooters require a distinct workshop playbook: CVT belt/roller/clutch maintenance creates recurring work that chain-drive underbones do not.
A21: Commuter scooter | B21: =COUNTIF('Malaysia Model Catalogue'!$C$5:$C$331,A21) | C21: Catalogue breadth only - not sales share | G21: 3 | H21: Malaysia is highly fragmented beyond the leading Japanese brands. Multi-brand distributors materially expand the number of brands and service/parts complexity.
A22: Premium / mid scooter | B22: =COUNTIF('Malaysia Model Catalogue'!$C$5:$C$331,A22) | C22: Catalogue breadth only - not sales share | G22: 4 | H22: EV changes the revenue mix rather than eliminating service: oil/engine work falls, while tyres, brakes, battery health, HV diagnostics, electronics and fleet uptime become more important.
A23: Naked / standard / roadster | B23: =COUNTIF('Malaysia Model Catalogue'!$C$5:$C$331,A23) | C23: Catalogue breadth only - not sales share | G23: 5 | H23: Authorized networks win on warranty, recalls, OEM diagnostics and genuine parts; independents compete on convenience, price, multi-brand capability, overhaul and specialist tuning.
A24: Sport / supersport | B24: =COUNTIF('Malaysia Model Catalogue'!$C$5:$C$331,A24) | C24: Catalogue breadth only - not sales share | G24: 6 | H24: The service market should be segmented by capability tier, not only by workshop name: quick-service, general repair, diagnostics/specialist, performance/EV.
A25: Adventure touring (ADV) | B25: =COUNTIF('Malaysia Model Catalogue'!$C$5:$C$331,A25) | C25: Catalogue breadth only - not sales share | G25: 7 | H25: Data discipline matters: “current retail”, “parts support”, “dealer listed” and “upcoming” are explicitly separated to avoid false inventory assumptions.
A26: Cruiser / bobber | B26: =COUNTIF('Malaysia Model Catalogue'!$C$5:$C$331,A26) | C26: Catalogue breadth only - not sales share
A27: Modern classic / retro roadster | B27: =COUNTIF('Malaysia Model Catalogue'!$C$5:$C$331,A27) | C27: Catalogue breadth only - not sales share
A28: Electric commuter scooter | B28: =COUNTIF('Malaysia Model Catalogue'!$C$5:$C$331,A28) | C28: Catalogue breadth only - not sales share
A29: Electric fleet / delivery | B29: =COUNTIF('Malaysia Model Catalogue'!$C$5:$C$331,A29) | C29: Catalogue breadth only - not sales share
G31: Important Caveats
G32: • Model/dealer availability changes rapidly; use Source URL + status before procurement or commercial decisions.
G33: • Parts/support footprint rows are deliberately not counted as proof of current showroom inventory.
G34: • Service intervals and repair procedures must follow each OEM manual.
G35: • Provider examples validate service archetypes; they are not a complete directory of Malaysia workshops.
G36: • Official registration data and third-party industry estimates are kept separate.

Sheet Motorcycle Taxonomy
A1: Motorcycle Taxonomy - Malaysia Lens
A2: A practical classification of motorcycle body styles and use cases. Relevance reflects the Malaysian market, not global production volumes.
A4: Primary Type | B4: Common Malaysia Term | C4: Typical Configuration | D4: Typical Engine / Power Band | E4: Transmission | F4: Primary Use Case | G4: Malaysia Relevance | H4: Relevance Score (1-5) | I4: Common Buyer Profile | J4: Service Pattern | K4: Representative Malaysia Examples | L4: Commercial / Workshop Note | M4: Source / Basis
A5: Underbone / commuter moped | B5: Kapcai / cub | C5: Step-through/underbone frame, 17-inch wheels, chain drive | D5: 90-185 cc | E5: 4-6 speed semi-auto/manual | F5: Daily commute, delivery, suburban/rural mobility | G5: Very High | H5: 5 | I5: Mass commuter, student, gig rider | J5: Frequent oil, chain/sprocket, tyres, brake wear | K5: Honda Wave Alpha / Dash125 / RS-X; Yamaha 135LC / Y15ZR / Y16ZR; Modenas Kriss; Aveta VS115 | L5: Highest-frequency service funnel; price and turnaround time matter. | M5: https://boonsiewhonda.com.my/product/
A6: Lifestyle cub / mini-underbone | B6: Cub / retro kapcai | C6: Small-displacement upright bike, often scrambler/cub styling | D6: 110-125 cc | E6: Semi-auto/manual | F6: Urban lifestyle + light trail | G6: High | H6: 4 | I6: Younger lifestyle buyer, customizer | J6: Oil, chain, tyres; accessory/custom demand | K6: Yamaha PG-1; CFMOTO Papio; WMOTO Cub Classic 110 | L6: Accessories and visual customization add revenue beyond routine service. | M6: https://www.yamaha-motor.com.my/products/
A7: Commuter scooter | B7: Skuter | C7: Step-through body, under-seat storage, small wheels | D7: 110-160 cc | E7: CVT automatic | F7: Dense urban commuting | G7: Very High | H7: 5 | I7: Urban commuter, first-time rider | J7: Oil + CVT belt/roller/clutch + tyres/brakes | K7: Honda BeAT / Vario; Yamaha Ego / NMAX; Aveta Serra / Nova; SYM models | L7: CVT creates recurring service items not present on chain-drive kapcai. | M7: https://boonsiewhonda.com.my/product/
A8: Premium / mid scooter | B8: Premium scooter | C8: Larger scooter, stronger chassis/storage, ABS/TCS increasingly common | D8: 150-250 cc | E8: CVT automatic | F8: Urban + intercity | G8: High | H8: 4 | I8: Experienced commuter, touring-lite buyer | J8: CVT, coolant, brakes, tyres, diagnostics | K8: Honda NSS250; Yamaha XMAX250; Modenas Elegan EX; Kymco DTX250 | L8: Higher parts ticket and diagnostic content than entry scooters. | M8: https://www.modenas.my/
A9: Maxi-scooter | B9: Maxi scooter | C9: Large body, touring ergonomics, twin/single cylinder | D9: 300-750+ cc | E9: CVT/DCT/automatic depending model | F9: Highway touring + premium commuting | G9: Medium | H9: 3 | I9: Premium urban/touring rider | J9: CVT/DCT, coolant, premium tyres, brakes, electronics | K9: Yamaha TMAX; BMW C400GT; Honda X-ADV / ADV350; SYM Maxsym TL508 | L9: Lower volume but high-value service and tyre/brake tickets. | M9: https://www.bmw-motorrad.com.my/en/models/modeloverview.html
A10: Adventure / crossover scooter | B10: ADV scooter | C10: Scooter ergonomics with longer travel/rugged styling | D10: 150-750 cc | E10: CVT/DCT | F10: Urban + poor roads + touring | G10: High | H10: 4 | I10: Commuter seeking versatility | J10: CVT/DCT, suspension, tyres, body protection | K10: Honda ADV160 / X-ADV; Kymco DTX250; WMOTO XDV250i | L10: Growing crossover niche; suspension/tyre positioning differs from normal scooters. | M10: https://hondabigbike.com.my/
A11: Naked / standard / roadster | B11: Naked bike | C11: Upright road bike, exposed engine | D11: 150-1300+ cc | E11: Manual | F11: Street riding, weekend leisure | G11: High | H11: 4 | I11: Enthusiast + commuter | J11: Oil, chain, tyres, brakes, valve service, diagnostics | K11: Honda CB250R/CB650R; Yamaha MT series; Kawasaki Z; CFMOTO NK | L11: Wide price spectrum; strong aftermarket and tuning demand. | M11: https://www.cfmotomalaysia.com.my/
A12: Sport / supersport | B12: Sportbike / superbike | C12: Full fairing, forward-biased ergonomics | D12: 150-1100 cc | E12: Manual/quickshifter | F12: Performance street + track | G12: High | H12: 4 | I12: Performance enthusiast | J12: Premium tyres/brakes, chain, coolant, valve, diagnostics | K12: Honda CBR; Yamaha R series; Kawasaki Ninja/ZX; Suzuki GSX-R; CFMOTO SR | L12: High-value tyres, brake fluid/pads and crash/bodywork work. | M12: https://kawasaki.com.my/
A13: Sport touring | B13: Sport tourer | C13: Sport chassis with wind protection/luggage | D13: 650-1400 cc | E13: Manual/DCT | F13: Fast long-distance road touring | G13: Medium | H13: 3 | I13: Experienced touring rider | J13: Tyres, brakes, chain/shaft, fluids, electronics | K13: Yamaha Tracer 9 GT; Suzuki GSX-S1000GT/GX; KTM 890 SMT | L13: Mileage accumulation makes preventive maintenance and tyres important. | M13: https://www.suzuki.com.my/products
A14: Luxury / grand touring | B14: Touring bike | C14: Large fairing, luggage, electronics, passenger focus | D14: 1000-1800+ cc | E14: Manual/DCT/shaft | F14: Long-distance premium touring | G14: Niche | H14: 2 | I14: High-income touring rider | J14: Dealer diagnostics, shaft/fluids, premium tyres, electronics | K14: Honda Gold Wing Tour; BMW R1300RT/K1600GT; CFMOTO 1250TR-G | L14: Low volume, high ticket, specialized tooling and parts. | M14: https://hondabigbike.com.my/
A15: Adventure touring (ADV) | B15: ADV / adventure | C15: Upright, long-travel suspension, mixed wheel sizes | D15: 250-1300 cc | E15: Manual/DCT | F15: Touring + broken roads/light off-road | G15: High | H15: 4 | I15: Tourer, overlander, enthusiast | J15: Tyres, chain, suspension, protection, diagnostics | K15: Honda Africa Twin/Transalp/NX500; BMW GS; Suzuki V-Strom; CFMOTO MT | L15: High accessory attach rate: luggage, guards, tyres, suspension. | M15: https://www.bmw-motorrad.com.my/en/models/modeloverview.html
A16: Dual-sport / trail | B16: Trail bike | C16: Street-legal off-road oriented, 21/18 wheels common | D16: 150-700 cc | E16: Manual | F16: Trail + road | G16: Medium | H16: 3 | I16: Rural rider, trail enthusiast | J16: Air filter, chain, tyres, fork seals, bearings | K16: Honda CRF250 Rally; Suzuki DR-Z4S; CFMOTO 250 DUAL; KTM 690 Enduro R | L16: Dirt exposure accelerates filters, chains, bearings and fork-seal work. | M16: https://www.cfmotomalaysia.com.my/
... A27: Electric performance / road motorcycle | B27: Performance EV | C27: Motorcycle chassis with higher-output electric drive | D27: Varies | E27: Single-speed electric | F27: Premium urban/road | G27: Early Niche | H27: 1 | I27: Technology/premium early adopter | J27: HV diagnostics, battery/BMS/controller, tyres/brakes | K27: Selected MForce electric brands / emerging products | L27: Requires HV-safe procedures and OEM diagnostic access. | M27: https://www.qjmotor.mforce.my/news/list/2026/MFORCEMOTOXPERIENCE2026OVER100MOTORCYCLESAND15NEWMODELSSHOWCASEDATMALAYSIABIKESHOW/

Sheet Malaysia Model Catalogue
A1: Malaysia Motorcycle Model Catalogue - 2026 Snapshot
A2: Evidence-led model/family catalogue. Status distinguishes verified current retail, website-listed, dealer-listed, support/parts footprint, and announced/upcoming models. It is not a live inventory feed.
A4: Brand | B4: Model / Family | C4: Primary Type | D4: Subsegment | E4: Powertrain | F4: Approx cc / kW | G4: Engine / Power Class | H4: Transmission / Final Drive | I4: Malaysia Status | J4: Distributor / Group | K4: Evidence Confidence | L4: Market Note | M4: Source URL
A5: ARIIC | B5: GOBI 250 | C5: Adventure / crossover scooter | D5: Adventure scooter | E5: Petrol ICE | F5: 250 | G5: 151-250 cc | H5: Varies / see OEM specification | I5: 2026 MForce launch/showcase | J5: MForce | K5: High | L5: Named in MForce MotoXperience 2026 launch list | M5: https://www.qjmotor.mforce.my/news/list/2026/MFORCEMOTOXPERIENCE2026OVER100MOTORCYCLESAND15NEWMODELSSHOWCASEDATMALAYSIABIKESHOW/
A6: ARIIC | B6: TOUCH 250 | C6: Premium / mid scooter | D6: 250-class scooter | E6: Petrol ICE | F6: 250 | G6: 151-250 cc | H6: Varies / see OEM specification | I6: 2026 MForce launch/showcase | J6: MForce | K6: High | L6: Named in MForce MotoXperience 2026 launch list | M6: https://www.qjmotor.mforce.my/news/list/2026/MFORCEMOTOXPERIENCE2026OVER100MOTORCYCLESAND15NEWMODELSSHOWCASEDATMALAYSIABIKESHOW/
A7: AVETA | B7: Vanguard 250 | C7: Adventure / crossover scooter | D7: 250-class adventure scooter | E7: Petrol ICE | F7: 250 | G7: 151-250 cc | H7: CVT / belt | I7: Dealer-listed Malaysia 2026; verify local stock | J7: Aveta Malaysia / dealer network | K7: Medium | L7: Dealer-listed | M7: https://www.chj.com.my/shop/aveta
A8: AVETA | B8: VTM 250 | C8: Adventure touring (ADV) | D8: Quarter-litre adventure | E8: Petrol ICE | F8: 250 | G8: 151-250 cc | H8: Manual / chain | I8: Dealer-listed Malaysia 2026; verify local stock | J8: Aveta Malaysia / dealer network | K8: Medium | L8: Dealer-listed | M8: https://www.chj.com.my/shop/aveta
A9: AVETA | B9: Bellagio 125 | C9: Commuter scooter | D9: Retro scooter | E9: Petrol ICE | F9: 125 | G9: <=125 cc | H9: CVT / belt | I9: Dealer-listed Malaysia 2026; verify local stock | J9: Aveta Malaysia / dealer network | K9: Medium | L9: Dealer-listed | M9: https://www.chj.com.my/shop/aveta
A10: AVETA | B10: Nova 125 | C10: Commuter scooter | D10: Commuter scooter | E10: Petrol ICE | F10: 125 | G10: <=125 cc | H10: CVT / belt | I10: Dealer-listed Malaysia 2026; verify local stock | J10: Aveta Malaysia / dealer network | K10: Medium | L10: Dealer-listed | M10: https://www.chj.com.my/shop/aveta
A11: AVETA | B11: Nova 160 | C11: Commuter scooter | D11: Commuter scooter | E11: Petrol ICE | F11: 160 | G11: 151-250 cc | H11: CVT / belt | I11: Dealer-listed Malaysia 2026; verify local stock | J11: Aveta Malaysia / dealer network | K11: Medium | L11: Dealer-listed | M11: https://www.chj.com.my/shop/aveta
A12: AVETA | B12: Nova 160 SE | C12: Commuter scooter | D12: Commuter scooter | E12: Petrol ICE | F12: 160 | G12: 151-250 cc | H12: CVT / belt | I12: Dealer-listed Malaysia 2026; verify local stock | J12: Aveta Malaysia / dealer network | K12: Medium | L12: Dealer-listed | M12: https://www.chj.com.my/shop/aveta
A13: AVETA | B13: Serra 125 | C13: Commuter scooter | D13: Entry scooter | E13: Petrol ICE | F13: 125 | G13: <=125 cc | H13: CVT / belt | I13: Current launch - Malaysia Apr 2026 | J13: Aveta Malaysia | K13: High | L13: Officially reported 2026 launch | M13: https://www.rodaroda.my/articles/model-baru/4279/aveta-perkenalkan-3-model-terkini-serra-125-vs115-dan-nova-200
A14: AVETA | B14: Viper 180 | C14: Commuter scooter | D14: Sport scooter | E14: Petrol ICE | F14: 180 | G14: 151-250 cc | H14: CVT / belt | I14: Dealer-listed Malaysia 2026; verify local stock | J14: Aveta Malaysia / dealer network | K14: Medium | L14: Dealer-listed | M14: https://www.chj.com.my/shop/aveta
A15: AVETA | B15: Ranger Max Explorer | C15: Lifestyle cub / mini-underbone | D15: Adventure moped | E15: Petrol ICE | F15: 130 | G15: 126-150 cc | H15: Semi-auto / chain | I15: Dealer-listed Malaysia 2026; verify local stock | J15: Aveta Malaysia / dealer network | K15: Medium | L15: Dealer-listed | M15: https://www.chj.com.my/shop/aveta
A16: AVETA | B16: Marvel 150 | C16: Naked / standard / roadster | D16: Street/lifestyle | E16: Petrol ICE | F16: 150 | G16: 126-150 cc | H16: Manual / chain | I16: Dealer-listed Malaysia 2026; verify local stock | J16: Aveta Malaysia / dealer network | K16: Medium | L16: Dealer-listed | M16: https://www.chj.com.my/shop/aveta
... A47: Benelli | B47: RFS150i | C47: Underbone / commuter moped | D47: Sport underbone | E47: Petrol ICE | F47: 150 | G47: 126-150 cc | H47: Manual / chain | I47: Current/website-visible models; selected support footprint | J47: MForce | K47: Medium-High | L47: Website/parts footprint | M47: https://www.benelli.mforce.my/
A48: Blueshark | B48: R1 | C48: Electric commuter scooter | D48: Smart electric scooter | E48: Electric | H48: Electric single speed | I48: Current Malaysia product/support ecosystem | J48: Blueshark Malaysia | K48: High | L48: Battery swap and home-charging ecosystem; EV aftersales channel expanding. | M48: https://blueshark.com.my/r-series/overview
A49: BMW Motorrad | B49: F 450 GS | C49: Adventure touring (ADV) | D49: Entry/middle ADV | E49: Petrol ICE | F49: 450 | G49: 251-500 cc | H49: Manual / chain | I49: Current retail - official Malaysia model overview | J49: BMW Malaysia | K49: High | L49: Current model overview | M49: https://www.bmw-motorrad.com.my/en/models/modeloverview.html
A50: BMW Motorrad | B50: R 1300 GS | C50: Adventure touring (ADV) | D50: Large ADV | E50: Petrol ICE | F50: 1300 | G50: >1000 cc | H50: Manual / shaft | I50: Current retail - official Malaysia model overview | J50: BMW Malaysia | K50: High | L50: Current model overview | M50: https://www.bmw-motorrad.com.my/en/models/modeloverview.html
A51: BMW Motorrad | B51: R 1300 GS Adventure | C51: Adventure touring (ADV) | D51: Large ADV | E51: Petrol ICE | F51: 1300 | G51: >1000 cc | H51: Manual / shaft | I51: Current retail - official Malaysia model overview | J51: BMW Malaysia | K51: High | L51: Current model overview | M51: https://www.bmw-motorrad.com.my/en/models/modeloverview.html
A52: BMW Motorrad | B52: R 12 | C52: Cruiser / bobber | D52: Heritage cruiser | E52: Petrol ICE | F52: 1170 | G52: >1000 cc | H52: Manual / shaft | I52: Current retail - official Malaysia model overview | J52: BMW Malaysia | K52: High | L52: Current model overview | M52: https://www.bmw-motorrad.com.my/en/models/modeloverview.html
A53: BMW Motorrad | B53: K 1600 GT | C53: Luxury / grand touring | D53: Touring | E53: Petrol ICE | F53: 1649 | G53: >1000 cc | H53: Manual / shaft | I53: Current retail - official Malaysia model overview | J53: BMW Malaysia | K53: High | L53: Current model overview | M53: https://www.bmw-motorrad.com.my/en/models/modeloverview.html
A54: BMW Motorrad | B54: R 1300 RT | C54: Luxury / grand touring | D54: Touring | E54: Petrol ICE | F54: 1300 | G54: >1000 cc | H54: Manual / shaft | I54: Current retail - official Malaysia model overview | J54: BMW Malaysia | K54: High | L54: Current model overview | M54: https://www.bmw-motorrad.com.my/en/models/modeloverview.html
A55: BMW Motorrad | B55: C 400 GT | C55: Maxi-scooter | D55: Premium scooter | E55: Petrol ICE | F55: 350 | G55: 251-500 cc | H55: CVT / belt | I55: Current retail - official Malaysia model overview | J55: BMW Malaysia | K55: High | L55: Current model overview | M55: https://www.bmw-motorrad.com.my/en/models/modeloverview.html
A56: BMW Motorrad | B56: R 12 nineT | C56: Modern classic / retro roadster | D56: Heritage roadster | E56: Petrol ICE | F56: 1170 | G56: >1000 cc | H56: Manual / shaft | I56: Current retail - official Malaysia model overview | J56: BMW Malaysia | K56: High | L56: Current model overview | M56: https://www.bmw-motorrad.com.my/en/models/modeloverview.html
A57: BMW Motorrad | B57: S 1000 RR | C57: Sport / supersport | D57: Superbike | E57: Petrol ICE | F57: 999 | G57: 751-1000 cc | H57: Manual / chain | I57: Current retail - official Malaysia model overview | J57: BMW Malaysia | K57: High | L57: Current model overview | M57: https://www.bmw-motorrad.com.my/en/models/modeloverview.html
A58: BMW Motorrad | B58: S 1000 XR | C58: Sport touring | D58: Sport crossover | E58: Petrol ICE | F58: 999 | G58: 751-1000 cc | H58: Manual / chain | I58: Current retail - official Malaysia model overview | J58: BMW Malaysia | K58: High | L58: Current model overview | M58: https://www.bmw-motorrad.com.my/en/models/modeloverview.html
A59: BRIXTON | B59: 625V | C59: Cruiser / bobber | D59: Middleweight V-twin cruiser | E59: Petrol ICE | F59: 625 | G59: 501-750 cc | H59: Varies / see OEM specification | I59: 2026 MForce launch/showcase | J59: MForce | K59: High | L59: Named in MForce MotoXperience 2026 launch list | M59: https://www.qjmotor.mforce.my/news/list/2026/MFORCEMOTOXPERIENCE2026OVER100MOTORCYCLESAND15NEWMODELSSHOWCASEDATMALAYSIABIKESHOW/
A60: CFMOTO | B60: 1000MT-X | C60: Adventure touring (ADV) | D60: Large ADV | E60: Petrol ICE | F60: 1000 | G60: 751-1000 cc | H60: Manual / chain | I60: Current website-listed - official Malaysia | J60: CFMOTO Malaysia / MForce | K60: High | L60: 2026 launch / official product page | M60: https://www.cfmotomalaysia.com.my/
... A87: CFMOTO | B87: 650GT | C87: Sport touring | D87: Grand touring | E87: Petrol ICE | F87: 650 | G87: 501-750 cc | H87: Manual / chain | I87: Current website-listed - official Malaysia | J87: CFMOTO Malaysia / MForce | K87: High | L87: Official product page | M87: https://www.cfmotomalaysia.com.my/
A88: CYCLONE | B88: RT5 | C88: Maxi-scooter | D88: Maxi scooter | E88: Petrol ICE | H88: Varies / see OEM specification | I88: 2026 MForce launch/showcase | J88: MForce | K88: High | L88: Named in MForce MotoXperience 2026 launch list | M88: https://www.qjmotor.mforce.my/news/list/2026/MFORCEMOTOXPERIENCE2026OVER100MOTORCYCLESAND15NEWMODELSSHOWCASEDATMALAYSIABIKESHOW/
A89: CYCLONE | B89: RT2S | C89: Premium / mid scooter | D89: Touring scooter | E89: Petrol ICE | H89: Varies / see OEM specification | I89: 2026 MForce launch/showcase | J89: MForce | K89: High | L89: Named in MForce MotoXperience 2026 launch list | M89: https://www.qjmotor.mforce.my/news/list/2026/MFORCEMOTOXPERIENCE2026OVER100MOTORCYCLESAND15NEWMODELSSHOWCASEDATMALAYSIABIKESHOW/
A90: Ducati | B90: DesertX family | C90: Adventure touring (ADV) | D90: Model family | E90: Petrol ICE | H90: Manual / chain | I90: Malaysia/APAC family - local distributor/trim should be verified | J90: Ducati Asia Pacific | K90: Medium | L90: Family-level record; dealer/distributor arrangements and exact local model-year availability can change. | M90: https://ducatiasiapacific.com/malaysia/
A91: Ducati | B91: Multistrada family | C91: Adventure touring (ADV) | D91: Model family | E91: Petrol ICE | H91: Manual / chain | I91: Malaysia/APAC family - local distributor/trim should be verified | J91: Ducati Asia Pacific | K91: Medium | L91: Family-level record; dealer/distributor arrangements and exact local model-year availability can change. | M91: https://ducatiasiapacific.com/malaysia/
A92: Ducati | B92: Diavel / XDiavel family | C92: Cruiser / bobber | D92: Model family | E92: Petrol ICE | H92: Manual / chain | I92: Malaysia/APAC family - local distributor/trim should be verified | J92: Ducati Asia Pacific | K92: Medium | L92: Family-level record; dealer/distributor arrangements and exact local model-year availability can change. | M92: https://ducatiasiapacific.com/malaysia/
A93: Ducati | B93: Desmo450 MX family | C93: Motocross / competition off-road | D93: Model family | E93: Petrol ICE | H93: Manual / chain | I93: Malaysia/APAC family - local distributor/trim should be verified | J93: Ducati Asia Pacific | K93: Medium | L93: Family-level record; dealer/distributor arrangements and exact local model-year availability can change. | M93: https://ducatiasiapacific.com/malaysia/
A94: Ducati | B94: Monster family | C94: Naked / standard / roadster | D94: Model family | E94: Petrol ICE | H94: Manual / chain | I94: Malaysia/APAC family - local distributor/trim should be verified | J94: Ducati Asia Pacific | K94: Medium | L94: Family-level record; dealer/distributor arrangements and exact local model-year availability can change. | M94: https://ducatiasiapacific.com/malaysia/
A95: Ducati | B95: Streetfighter family | C95: Naked / standard / roadster | D95: Model family | E95: Petrol ICE | H95: Manual / chain | I95: Malaysia/APAC family - local distributor/trim should be verified | J95: Ducati Asia Pacific | K95: Medium | L95: Family-level record; dealer/distributor arrangements and exact local model-year availability can change. | M95: https://ducatiasiapacific.com/malaysia/
A96: Ducati | B96: Scrambler family | C96: Scrambler / cafe / heritage special | D96: Model family | E96: Petrol ICE | H96: Manual / chain | I96: Malaysia/APAC family - local distributor/trim should be verified | J96: Ducati Asia Pacific | K96: Medium | L96: Family-level record; dealer/distributor arrangements and exact local model-year availability can change. | M96: https://ducatiasiapacific.com/malaysia/
A97: Ducati | B97: Panigale family | C97: Sport / supersport | D97: Model family | E97: Petrol ICE | H97: Manual / chain | I97: Malaysia/APAC family - local distributor/trim should be verified | J97: Ducati Asia Pacific | K97: Medium | L97: Family-level record; dealer/distributor arrangements and exact local model-year availability can change. | M97: https://ducatiasiapacific.com/malaysia/
...

Sheet Brand & Distributor Map
A1: Brand, Distributor & After-Sales Map - Malaysia
A2: A market-structure view. “Network signal” is evidence of an after-sales channel, not a complete dealer-count census unless a count is explicitly sourced.
A4: Brand / Portfolio | B4: Malaysia Distributor / Group | C4: Core Segment | D4: Market Position / Role | E4: After-sales Channel Signal | F4: Known Network / Footprint Signal | G4: Evidence Quality | H4: Key Caveat | I4: Source URL | J4: Snapshot Date
A5: Honda | B5: Boon Siew Honda | C5: Mass commuter to premium big bike | D5: Market-leading scale brand; broad ICE portfolio | E5: Authorized dealers + Honda BigWing/BigBike + genuine parts/maintenance programs | F5: Nationwide authorized ecosystem; exact current count not stated here | G5: High | H5: Dealer count not estimated without official census | I5: https://boonsiewhonda.com.my/product/ | J5: 2026-08-18
A6: Yamaha | B6: Hong Leong Yamaha Motor | C6: Mass commuter, scooter, sport, big bike | D6: Very strong underbone/scooter franchise | E6: 3S / Star Center + Yamaha Quality Service (YQS) + Yamaha Genuine Parts | F6: 260+ YQS locations stated by Yamaha | G6: High | H6: YQS count is service points, not necessarily unique full dealerships | I6: https://www.yamaha-motor.com.my/servis-yamaha-sentiasa-dekat-dengan-anda/ | J6: 2026-08-18
A7: Suzuki | B7: Suzuki Malaysia | C7: Underbone to superbike/ADV | D7: Broad but smaller-volume multi-segment brand | E7: Suzuki Exclusive Service Centre + Suzuki Service Corner | F7: By-state service-centre directory | G7: High | H7: No aggregate outlet count used | I7: https://www.suzuki.com.my/products | J7: 2026-08-18
A8: Kawasaki | B8: MODENAS / Kawasaki Malaysia | C8: Sport, naked, ADV, cruiser, off-road | D8: Premium/performance plus legacy quarter-litre strength | E8: MODENAS/Kawasaki authorized network | F8: Service through authorized ecosystem | G8: High | H8: Individual model availability varies by model year | I8: https://kawasaki.com.my/ | J8: 2026-08-18
A9: MODENAS | B9: DRB-HICOM | C9: Commuter, scooter, EV; Kawasaki-linked big bikes | D9: National brand with ICE + EV transition | E9: Service Plus dealers/service centres | F9: 31 Service Plus locations visible in official listing snapshot | G9: High | H9: Count is the official listing result at snapshot date | I9: https://www.modenas.my/service-plus/service-plus-dealer | J9: 2026-08-18
A10: CFMOTO | B10: CFMOTO Malaysia / MForce | C10: Naked, sport, ADV, touring | D10: Fast-expanding Chinese premium/value brand | E10: Dealer list + MForce service/parts ecosystem | F10: Broad model page spanning 250 cc to 1250 tourer | G10: High | H10: Model page may include carryover models; confirm dealer stock | I10: https://www.cfmotomalaysia.com.my/ | J10: 2026-08-18
A11: MForce portfolio | B11: MForce Bike Holdings | C11: Mass commuter to premium, ICE + EV | D11: Major multi-brand distribution platform | E11: MForce authorized dealers + brand parts sites + KL service centre | F11: 2026 release states 23 brands and >100 motorcycles at show | G11: High | H11: Release states 23 brands, while the named list contains 24 labels as transcribed; counting convention/brand-label treatment is therefore ambiguous. | I11: https://www.qjmotor.mforce.my/news/list/2026/MFORCEMOTOXPERIENCE2026OVER100MOTORCYCLESAND15NEWMODELSSHOWCASEDATMALAYSIABIKESHOW/ | J11: 2026-08-18
A12: Benelli | B12: MForce | C12: Naked, ADV, classic, scooter | D12: Established MForce portfolio brand | E12: Authorized dealers + online parts/support footprint | F12: Extensive spare-parts model history | G12: Medium-High | H12: Parts footprint includes legacy models; not equal to current showroom stock | I12: https://www.benelli.mforce.my/spareparts/ | J12: 2026-08-18
A13: QJMOTOR | B13: MForce | C13: Sport, ADV, cruiser, scooter, EV | D13: Rapidly expanding multi-segment challenger | E13: Authorized dealers + online parts | F13: Products/support span roughly 100-1300 cc per distributor description | G13: High | H13: Parts page can include non-current retail models | I13: https://www.qjmotor.mforce.my/spareparts/ | J13: 2026-08-18
A14: SYM | B14: MForce | C14: Scooters + underbones | D14: Scooter-focused established brand | E14: MForce dealer/service + parts | F14: Multiple active scooter/underbone products | G14: Medium-High | H14: Exact dealer count not captured | I14: https://www.sym.mforce.my/ | J14: 2026-08-18
A15: WMOTO | B15: MForce | C15: Scooters, commuters, cruiser | D15: Malaysia-oriented value brand under MForce | E15: MForce authorized dealers + parts | F15: Broad support footprint, with 2025/2026 launches | G15: Medium-High | H15: Support footprint includes legacy models | I15: https://www.wmoto.mforce.my/spareparts/ | J15: 2026-08-18
... A25: Blueshark | B25: Blueshark Malaysia | C25: Electric scooter | D25: Smart EV / battery ecosystem | E25: Own EV support plus selected PETRONAS MotoExpert support collaboration | F25: Five selected PETRONAS MotoExpert outlets announced for initial onboarding | G25: High | H25: EV aftersales network is still developing | I25: https://bernama.com/en/press/news.php?id=2555492 | J25: 2026-08-18

Sheet Market Signals
A1: Malaysia Motorcycle Market Signals - 2026
A2: Official registration figures are separated from third-party industry estimates. Derived shares are formulas so the workbook remains auditable.
A4: Metric | B4: Value | C4: Unit | D4: Evidence Type | E4: Calculation / Interpretation | F4: Source URL | G4: As-of / Period | H4: Confidence
A5: Motorcycle registrations - June 2026 | B5: 65988 | C5: units | D5: Official government | E5: Monthly registrations | F5: https://data.gov.my/dashboard/vehicle-registrations/motorcycle | G5: June 2026 | H5: High
A6: Petrol motorcycle registrations - June 2026 | B6: 64195 | C6: units | D6: Official government | E6: Monthly petrol registrations | F6: https://data.gov.my/dashboard/vehicle-registrations/motorcycle | G6: June 2026 | H6: High
A7: Electric motorcycle registrations - June 2026 | B7: 1792 | C7: units | D7: Official government | E7: Monthly electric registrations | F7: https://data.gov.my/dashboard/vehicle-registrations/motorcycle | G7: June 2026 | H7: High
A8: Cumulative motorcycles registered since 2000 | B8: 13465638 | C8: units | D8: Official government | E8: Cumulative total | F8: https://data.gov.my/dashboard/vehicle-registrations/motorcycle | G8: 2000-Jun 2026 | H8: High
A9: Cumulative petrol motorcycles since 2000 | B9: 13434232 | C9: units | D9: Official government | E9: Cumulative petrol | F9: https://data.gov.my/dashboard/vehicle-registrations/motorcycle | G9: 2000-Jun 2026 | H9: High
A10: Cumulative electric motorcycles since 2000 | B10: 30438 | C10: units | D10: Official government | E10: Cumulative electric | F10: https://data.gov.my/dashboard/vehicle-registrations/motorcycle | G10: 2000-Jun 2026 | H10: High
A11: Industry-estimated H1 2026 sales | B11: 378286 | C11: units | D11: Third-party industry estimate | E11: Use as directional market-size signal, not official registration total | F11: https://www.motorcyclesdata.com/2026/07/26/malaysia-motorcycles/ | G11: H1 2026 | H11: Medium
A12: Industry-estimated full-year 2025 sales | B12: 685670 | C12: units | D12: Third-party industry estimate | E12: Directional historical benchmark | F12: https://www.motorcyclesdata.com/2026/07/26/malaysia-motorcycles/ | G12: 2025 | H12: Medium
A13: Industry-estimated H1 2026 growth | B13: 0.1 | C13: % | D13: Third-party industry estimate | E13: Reported year-on-year growth | F13: https://www.motorcyclesdata.com/2026/07/26/malaysia-motorcycles/ | G13: H1 2026 | H13: Medium
A14: MForce portfolio brands stated at MotoXperience 2026 | B14: 23 | C14: brands | D14: Distributor release | E14: Stated total in release | F14: https://www.qjmotor.mforce.my/news/list/2026/MFORCEMOTOXPERIENCE2026OVER100MOTORCYCLESAND15NEWMODELSSHOWCASEDATMALAYSIABIKESHOW/ | G14: 29 May 2026 | H14: High
A15: MForce motorcycles showcased at MotoXperience 2026 | B15: 100 | C15: motorcycles | D15: Distributor release | E15: Release states more than 100; 100 used as conservative floor | F15: https://www.qjmotor.mforce.my/news/list/2026/MFORCEMOTOXPERIENCE2026OVER100MOTORCYCLESAND15NEWMODELSSHOWCASEDATMALAYSIABIKESHOW/ | G15: 29 May 2026 | H15: High
A16: Yamaha Quality Service locations | B16: 260 | C16: locations | D16: OEM statement | E16: Release states 260+ locations | F16: https://www.yamaha-motor.com.my/servis-yamaha-sentiasa-dekat-dengan-anda/ | G16: 2026 snapshot | H16: High
A17: MODENAS Service Plus locations | B17: 31 | C17: locations | D17: OEM listing | E17: Official service-plus dealer/service-centre listing count | F17: https://www.modenas.my/service-plus/service-plus-dealer | G17: 2026 snapshot | H17: High
A20: Derived Indicators
A21: Derived Metric | B21: Formula Result | C21: Unit | D21: Formula | E21: Interpretation | F21: Source Basis | G21: Period | H21: Caution
A22: Electric share of June 2026 motorcycle registrations | B22: =B7/B5 | C22: % | D22: =B7/B5 | E22: EV is still a small share of monthly registrations, but materially above its cumulative installed-base share. | F22: Official JPJ/data.gov.my | G22: June 2026 | H22: Single-month mix; can be volatile.
A23: Petrol share of June 2026 motorcycle registrations | B23: =B6/B5 | C23: % | D23: =B6/B5 | E23: ICE remains dominant in monthly registrations. | F23: Official JPJ/data.gov.my | G23: June 2026 | H23: Single-month mix.
A24: Electric share of cumulative registrations since 2000 | B24: =B10/B8 | C24: % | D24: =B10/B8 | E24: Installed-base EV penetration remains very low compared with new-registration mix. | F24: Official JPJ/data.gov.my | G24: 2000-Jun 2026 | H24: Cumulative registrations are not the same as active vehicles on road.
A25: Simple H1 2026 annualized industry pace | B25: =B11*2 | C25: units | D25: =B11*2 | E25: Arithmetic annualization only; illustrates scale if H2 matched H1. | F25: Third-party industry estimate | G25: 2026 annualized | H25: Not a forecast; ignores seasonality and macro changes.
A28: Powertrain | B28: June 2026 Registrations
A29: Petrol | B29: =B6
A30: Electric | B30: =B7

Sheet Service Taxonomy
A1: Motorcycle Service Taxonomy - Malaysia
A2: Service map across routine maintenance, repair, specialist work, roadside, claims and EV. Intervals are deliberately generalized because OEM schedules differ by model.
A4: Service Family | B4: Service Item | C4: Typical Trigger / Interval | D4: Applies Most To | E4: Capability Tier | F4: Key Tools / Skill | G4: Parts Dependency | H4: Repeat Frequency | I4: Urgency | J4: Typical Provider Type | K4: Malaysia Availability | L4: Commercial / Operational Note | M4: Source / Basis URL
A5: Routine maintenance | B5: Engine oil change | C5: Mileage/time per owner manual | D5: All ICE motorcycles | E5: Tier 1 - quick service | F5: Basic hand tools, waste-oil handling | G5: Oil/washer/filter depending model | H5: High | I5: Planned | J5: All workshops | K5: Very High | L5: Core recurring traffic driver. | M5: https://www.yamaha-motor.com.my/servis-yamaha-sentiasa-dekat-dengan-anda/
A6: Routine maintenance | B6: Oil filter replacement | C6: Mileage per owner manual | D6: Many ICE motorcycles | E6: Tier 1 - quick service | F6: Basic tools | G6: Model-specific filter | H6: Medium-High | I6: Planned | J6: General / authorized | K6: Very High | L6: Usually bundled with oil service. | M6: https://www.yamaha-motor.com.my/servis-yamaha-sentiasa-dekat-dengan-anda/
A7: Routine maintenance | B7: Scooter final-drive / gear oil | C7: Mileage per owner manual | D7: CVT scooters | E7: Tier 1 - quick service | F7: Basic tools | G7: Gear oil/seals | H7: Medium | I7: Planned | J7: General / scooter specialist | K7: High | L7: Distinct recurring scooter item. | M7: https://www.yamaha-motor.com.my/servis-yamaha-sentiasa-dekat-dengan-anda/
A8: Routine maintenance | B8: Air filter inspection/replacement | C8: Time/mileage; earlier in dusty use | D8: All ICE; especially off-road | E8: Tier 1 - quick service | F8: Basic access tools | G8: Model-specific filter | H8: Medium | I8: Planned | J8: All workshops | K8: Very High | L8: Off-road/dust use increases frequency. | M8: https://www.yamaha-motor.com.my/servis-yamaha-sentiasa-dekat-dengan-anda/
A9: Routine maintenance | B9: Spark plug replacement | C9: Mileage/condition | D9: ICE motorcycles | E9: Tier 1 - quick service | F9: Plug tools / torque practice | G9: Model-specific plug | H9: Medium | I9: Planned | J9: All workshops | K9: Very High | L9: Easy scheduled maintenance/upsell. | M9: https://www.yamaha-motor.com.my/servis-yamaha-sentiasa-dekat-dengan-anda/
A10: Routine maintenance | B10: Valve-clearance inspection/adjustment | C10: OEM mileage schedule | D10: 4-stroke ICE | E10: Tier 2 - general repair | F10: Feeler gauges, timing knowledge | G10: Shims/gaskets may be needed | H10: Low-Medium | I10: Planned | J10: General skilled / authorized | K10: High | L10: Labour-intensive; model knowledge matters. | M10: https://www.yamaha-motor.com.my/servis-yamaha-sentiasa-dekat-dengan-anda/
A11: Cooling | B11: Coolant replacement / bleed | C11: Time/mileage per manual | D11: Liquid-cooled motorcycles | E11: Tier 2 - general repair | F11: Bleeding procedure | G11: Coolant/seals | H11: Low-Medium | I11: Planned | J11: General / authorized | K11: High | L11: Important on higher-output and urban-heat use. | M11: https://www.cdmotorsport.my/perkhidmatan/
A12: Fuel / intake | B12: Throttle-body / injector cleaning | C12: Condition / diagnostics | D12: Fuel-injected ICE | E12: Tier 2 - general repair | F12: Injector/throttle cleaning, diagnostics | G12: Cleaner/seals | H12: Low-Medium | I12: Condition | J12: General / specialist | K12: High | L12: Demand rises with rough idle/poor response complaints. | M12: https://www.cdmotorsport.my/perkhidmatan/
A13: Fuel / intake | B13: Carburettor cleaning / tuning | C13: Condition / storage-related | D13: Older/budget carburetted bikes | E13: Tier 2 - general repair | F13: Carb tools, synchronization/mixture knowledge | G13: Jets/gaskets | H13: Condition-driven | I13: Medium | J13: General / specialist | K13: High | L13: Still relevant to legacy/common-on-road fleet. | M13: https://www.cdmotorsport.my/perkhidmatan/
A14: Engine | B14: Compression / leak-down diagnosis | C14: Symptoms / pre-overhaul | D14: ICE engines | E14: Tier 3 - diagnostics | F14: Compression/leak-down tools | G14: Low initially | H14: Condition-driven | I14: High | J14: Specialist / advanced general | K14: Medium-High | L14: Prevents premature overhaul decisions. | M14: https://www.cdmotorsport.my/perkhidmatan/
A15: Engine | B15: Top-end repair / rebuild | C15: Wear/failure | D15: ICE motorcycles | E15: Tier 3 - advanced mechanical | F15: Engine timing, measurement, torque procedures | G15: High | H15: Low | I15: High | J15: Engine specialist / authorized | K15: High | L15: High-ticket but lower frequency. | M15: https://www.cdmotorsport.my/perkhidmatan/
... A68: EV fleet | B68: Fleet preventive maintenance / uptime service | C68: Scheduled by fleet | D68: Delivery/fleet EVs | E68: Tier 3-4 | F68: Fleet scheduling + EV/mechanical | G68: Medium | H68: High | I68: Planned | J68: Fleet/OEM service | K68: Emerging | L68: High value comes from uptime, scheduling and SLA discipline. | M68: https://bernama.com/en/press/news.php?id=2555492

Sheet Service Provider Landscape
A1: Motorcycle Service Provider Landscape - Malaysia
A2: Representative national/OEM networks and independent/specialist service models. This is a landscape analysis, not a complete directory of every workshop.
A4: Provider / Network | B4: Provider Archetype | C4: Coverage Signal | D4: Service Scope | E4: Bike / Brand Focus | F4: Digital / Booking Signal | G4: Strengths | H4: Likely Gaps / Constraints | I4: Customer Trigger | J4: Evidence / Count | K4: Source URL | L4: Confidence
A5: Honda authorized after-sales | B5: OEM authorized network | C5: Nationwide brand ecosystem | D5: Scheduled maintenance, repair, genuine parts, warranty/recall | E5: Honda small bikes + BigBike | F5: Owner support / brand channels | G5: OEM procedures, parts, warranty linkage | H5: Brand-specific; premium big-bike work concentrated in specialized outlets | I5: Scheduled service / warranty / recall | J5: Official product/after-sales ecosystem | K5: https://boonsiewhonda.com.my/product/ | L5: High
A6: Yamaha Star Center / Star Shop + YQS | B6: OEM 3S + service standard network | C6: Nationwide; Yamaha states 260+ YQS | D6: Scheduled service, repair, genuine parts | E6: Yamaha | F6: E-service / dealer locator | G6: Very broad reach; standardized Yamaha procedures | H6: Brand-specific; service capability can differ by outlet tier | I6: Scheduled service / repair | J6: 260+ YQS locations | K6: https://www.yamaha-motor.com.my/servis-yamaha-sentiasa-dekat-dengan-anda/ | L6: High
A7: Suzuki Exclusive Service Centre / Service Corner | B7: OEM authorized network | C7: By-state directory | D7: Scheduled service, repair, genuine parts | E7: Suzuki | F7: Service-centre locator | G7: Brand-specific expertise from small to big bikes | H7: Smaller footprint than mass leaders | I7: Scheduled service / repair | J7: Official service centre categories | K7: https://www.suzuki.com.my/products | L7: High
A8: MODENAS Service Plus | B8: OEM/national-brand service network | C8: Official listing shows 31 service-plus locations | D8: Service/repair/parts across MODENAS portfolio | E8: MODENAS; linked Kawasaki/Kymco context varies by outlet | F8: Dealer locator | G8: National-brand support and formal service identity | H8: Outlet capability may vary by product/EV/big-bike specialization | I8: Scheduled service / repair | J8: 31 listed service-plus locations | K8: https://www.modenas.my/service-plus/service-plus-dealer | L8: High
A9: MForce multi-brand authorized ecosystem | B9: Multi-brand distributor authorized network | C9: National dealer network + KL office/service centre | D9: Service, warranty, genuine parts for many brands | E9: Benelli/QJ/SYM/WMOTO/VOGE/CFMOTO etc. depending authorization | F9: Brand sites/dealer lists/online parts | G9: Scale across many challenger brands; centralized parts structure | H9: Technician breadth and parts complexity across many brands | I9: Scheduled service / warranty / parts | J9: 2026 release: 23 brands, >100 bikes showcased | K9: https://www.qjmotor.mforce.my/news/list/2026/MFORCEMOTOXPERIENCE2026OVER100MOTORCYCLESAND15NEWMODELSSHOWCASEDATMALAYSIABIKESHOW/ | L9: High
A10: CFMOTO Malaysia dealer/service network | B10: OEM/distributor authorized | C10: Dealer list + MForce backing | D10: Maintenance, repair, parts | E10: CFMOTO 250-1250 class range | F10: Dealer locator | G10: Broad model coverage and growing installed base | H10: Advanced diagnostics and parts stocking must scale with model breadth | I10: Scheduled + enthusiast service | J10: Official Malaysia product/dealer ecosystem | K10: https://www.cfmotomalaysia.com.my/ | L10: High
A11: BMW Motorrad authorized service | B11: Premium OEM authorized | C11: Selected premium dealer/service network | D11: Scheduled maintenance, diagnostics, warranty, genuine parts | E11: BMW Motorrad | F11: Service booking / Service Inclusive | G11: High technical capability, OEM diagnostics, premium customer process | H11: Higher cost and geographically narrower reach | I11: Scheduled / warranty / electronics | J11: OEM service program | K11: https://www.bmw-motorrad.com.my/en/models/modeloverview.html | L11: High
A12: Royal Enfield authorized service | B12: OEM authorized | C12: Service-centre finder | D12: Routine service, repair, genuine parts | E12: Royal Enfield | F12: Service-centre locator | G12: Heritage-model expertise and genuine parts | H12: Brand-specific; niche footprint vs mass brands | I12: Scheduled / repair | J12: Official service locator | K12: https://www.royalenfield.com/my/en/motorcycles/ | L12: High
A13: Harley-Davidson authorized service | B13: Premium OEM authorized | C13: Petaling Jaya + authorized ecosystem | D13: Service, genuine parts, care, customization | E13: Harley-Davidson | F13: Book service | G13: Strong brand/custom expertise | H13: Premium/niche geographic footprint | I13: Scheduled / customization / touring prep | J13: PJ showroom/service evidence | K13: https://harleypj.com/showroom | L13: High
A14: KTM authorized service | B14: Premium/performance OEM | C14: Official service booking / dealer network | D14: Service, warranty, safety check, spare parts | E14: KTM road + off-road | F14: Book service + parts finder | G14: Performance/off-road know-how | H14: Older MY/current-stock complexity; specialist parts | I14: Scheduled / performance / off-road | J14: Official Malaysia service tools | K14: https://www.ktmmalaysia.com/spec-sheet/ | L14: High
A15: Triumph authorized dealers | B15: Premium OEM authorized | C15: Malaysia authorized dealers | D15: Maintenance, warranty, genuine parts | E15: Triumph | F15: Dealer/service booking channels | G15: OEM procedures and premium brand expertise | H15: Niche footprint | I15: Scheduled / warranty | J15: Official Malaysia site | K15: https://www.triumph-motorcycles.my/motorcycles | L15: High
... A23: Performance / dyno specialist archetype | B23: Specialist independent | C23: Concentrated in enthusiast markets | D23: Dyno, ECU tuning, exhaust/intake, suspension/brake setup | E23: Sport/naked/big bikes | F23: Appointment-based | G23: High skill/equipment differentiation | H23: Niche demand; legal/warranty implications of modifications | I23: Performance / modification | J23: Malaysia provider example confirms availability | K23: https://www.cdmotorsport.my/perkhidmatan/ | L23: Medium

Sheet Bike-Service Matrix
A1: Motorcycle Type x Service Demand Matrix
A2: H/M/L indicates relative service importance/frequency for each motorcycle type. The score is a formula: H=3, M=2, L=1 across ten service dimensions.
A4: Motorcycle Type | B4: Oil / Fluids | C4: CVT | D4: Chain / Final Drive | E4: Tyres | F4: Brakes | G4: Suspension | H4: Diagnostics / Electronics | I4: Engine Repair / Tune | J4: EV Battery / HV | K4: Roadside / Recovery | L4: Service Intensity Score | M4: Key Service Logic
A5: Underbone / commuter moped | B5: H | C5: L | D5: H | E5: H | F5: H | G5: M | H5: M | I5: M | J5: L | K5: H | L5: =COUNTIF(B5:K5,"H")*3+COUNTIF(B5:K5,"M")*2+COUNTIF(B5:K5,"L") | M5: High mileage + chain + consumables dominate.
A6: Lifestyle cub / mini-underbone | B6: H | C6: L | D6: H | E6: M | F6: M | G6: M | H6: M | I6: M | J6: L | K6: M | L6: =COUNTIF(B6:K6,"H")*3+COUNTIF(B6:K6,"M")*2+COUNTIF(B6:K6,"L") | M6: Routine service plus customization.
A7: Commuter scooter | B7: H | C7: H | D7: L | E7: H | F7: H | G7: M | H7: M | I7: M | J7: L | K7: H | L7: =COUNTIF(B7:K7,"H")*3+COUNTIF(B7:K7,"M")*2+COUNTIF(B7:K7,"L") | M7: CVT is a major recurring service stream.
A8: Premium / mid scooter | B8: H | C8: H | D8: L | E8: H | F8: H | G8: M | H8: H | I8: M | J8: L | K8: H | L8: =COUNTIF(B8:K8,"H")*3+COUNTIF(B8:K8,"M")*2+COUNTIF(B8:K8,"L") | M8: CVT + electronics + cooling/brakes.
A9: Maxi-scooter | B9: H | C9: H | D9: L | E9: H | F9: H | G9: H | H9: H | I9: M | J9: L | K9: H | L9: =COUNTIF(B9:K9,"H")*3+COUNTIF(B9:K9,"M")*2+COUNTIF(B9:K9,"L") | M9: Premium tyres/brakes/electronics and CVT/DCT complexity.
A10: Adventure / crossover scooter | B10: H | C10: H | D10: L | E10: H | F10: H | G10: H | H10: H | I10: M | J10: L | K10: H | L10: =COUNTIF(B10:K10,"H")*3+COUNTIF(B10:K10,"M")*2+COUNTIF(B10:K10,"L") | M10: Scooter drivetrain plus suspension/tyre stress.
A11: Naked / standard / roadster | B11: H | C11: L | D11: H | E11: H | F11: H | G11: M | H11: H | I11: H | J11: L | K11: H | L11: =COUNTIF(B11:K11,"H")*3+COUNTIF(B11:K11,"M")*2+COUNTIF(B11:K11,"L") | M11: Broad mechanical + tyre/brake + diagnostics demand.
A12: Sport / supersport | B12: H | C12: L | D12: H | E12: H | F12: H | G12: H | H12: H | I12: H | J12: L | K12: H | L12: =COUNTIF(B12:K12,"H")*3+COUNTIF(B12:K12,"M")*2+COUNTIF(B12:K12,"L") | M12: Premium consumables, crash risk and performance work.
A13: Sport touring | B13: H | C13: L | D13: H | E13: H | F13: H | G13: H | H13: H | I13: M | J13: L | K13: H | L13: =COUNTIF(B13:K13,"H")*3+COUNTIF(B13:K13,"M")*2+COUNTIF(B13:K13,"L") | M13: High mileage, tyres/brakes, electronics.
A14: Luxury / grand touring | B14: H | C14: L | D14: M | E14: H | F14: H | G14: H | H14: H | I14: M | J14: L | K14: H | L14: =COUNTIF(B14:K14,"H")*3+COUNTIF(B14:K14,"M")*2+COUNTIF(B14:K14,"L") | M14: Specialized OEM diagnostics and premium consumables.
A15: Adventure touring (ADV) | B15: H | C15: L | D15: H | E15: H | F15: H | G15: H | H15: H | I15: H | J15: L | K15: H | L15: =COUNTIF(B15:K15,"H")*3+COUNTIF(B15:K15,"M")*2+COUNTIF(B15:K15,"L") | M15: High mileage + mixed-surface wear + accessories.
A16: Dual-sport / trail | B16: H | C16: L | D16: H | E16: H | F16: H | G16: H | H16: M | I16: H | J16: L | K16: H | L16: =COUNTIF(B16:K16,"H")*3+COUNTIF(B16:K16,"M")*2+COUNTIF(B16:K16,"L") | M16: Dirt accelerates filters, chain, bearings, fork seals.
... A25: Electric performance / road motorcycle | B25: L | C25: L | D25: L | E25: H | F25: H | G25: H | H25: H | I25: L | J25: H | K25: H | L25: =COUNTIF(B25:K25,"H")*3+COUNTIF(B25:K25,"M")*2+COUNTIF(B25:K25,"L") | M25: Premium tyres/brakes + HV electronics.

Sheet Sources & Methodology
A1: Sources, Methodology & Caveats
A2: Research snapshot compiled 18 Aug 2026. Official government/OEM/distributor sources are preferred; third-party or dealer sources are explicitly tagged.
A4: Publisher / Source | B4: Source Type | C4: What It Supports | D4: URL | E4: Snapshot / Published Date | F4: Confidence | G4: Caveat / Use Rule | H4: Notes
A5: data.gov.my / JPJ vehicle registrations | B5: Official government | C5: June 2026 motorcycle registrations by fuel + cumulative totals | D5: https://data.gov.my/dashboard/vehicle-registrations/motorcycle | E5: Data as of 30 Jun 2026 | F5: High | G5: Treat as source of truth for registration snapshot | H5: Dashboard updated 10 Jul 2026 in search snapshot.
A6: data.gov.my motorcycle transaction catalogue | B6: Official government | C6: Maker/fuel/state transaction fields and evidence of active registration brands | D6: https://data.gov.my/data-catalogue/registration_transactions_motorcycle | E6: 2026 dataset | F6: High | G6: Transactional data; not a retail catalogue | H6: Useful for validating market fragmentation.
A7: MotorCyclesData | B7: Industry data / third party | C7: H1 2026 and 2025 market-size estimates | D7: https://www.motorcyclesdata.com/2026/07/26/malaysia-motorcycles/ | E7: 26 Jul 2026 | F7: Medium | G7: Directional only; do not mix with official JPJ totals without labeling | H7: Third-party industry estimate.
A8: Boon Siew Honda | B8: OEM/distributor official | C8: Honda small/mid lineup | D8: https://boonsiewhonda.com.my/product/ | E8: 2026 snapshot | F8: High | G8: Current web lineup; inventory can vary by dealer | H8: Official Malaysia site.
A9: Honda BigBike Malaysia | B9: OEM/distributor official | C9: Honda big-bike lineup | D9: https://hondabigbike.com.my/ | E9: 2026 snapshot | F9: High | G9: Current web lineup; inventory can vary | H9: Official Malaysia site.
A10: Hong Leong Yamaha Motor | B10: OEM/distributor official | C10: Yamaha products | D10: https://www.yamaha-motor.com.my/products/ | E10: 2026 snapshot | F10: High | G10: Current web products can include variants/limited editions | H10: Official Malaysia site.
A11: Yamaha Quality Service | B11: OEM/distributor official | C11: 260+ YQS service points | D11: https://www.yamaha-motor.com.my/servis-yamaha-sentiasa-dekat-dengan-anda/ | E11: 2026 snapshot | F11: High | G11: Count refers to YQS locations, not necessarily full 3S dealerships | H11: Official Yamaha statement.
A12: Suzuki Malaysia | B12: OEM/distributor official | C12: Current product range + service-centre categories | D12: https://www.suzuki.com.my/products | E12: 2026 snapshot | F12: High | G12: Inventory by dealer not guaranteed | H12: Official Malaysia site.
A13: Kawasaki Malaysia | B13: OEM/distributor official | C13: Current featured models and official families | D13: https://kawasaki.com.my/ | E13: 2026 snapshot | F13: High | G13: Family-level rows used when exact full current model list not captured | H13: Official Malaysia site.
A14: MODENAS | B14: OEM official | C14: MODENAS/Kymco/EV models and service ecosystem | D14: https://www.modenas.my/ | E14: 2026 snapshot | F14: High | G14: Model-year availability can vary | H14: Official Malaysia site.
A15: MODENAS Service Plus | B15: OEM official | C15: 31 Service Plus locations in listing snapshot | D15: https://www.modenas.my/service-plus/service-plus-dealer | E15: 2026 snapshot | F15: High | G15: Location count can change | H15: Official listing.
... A33: CD Motorsport | B33: Commercial provider | C33: Independent scope: overhaul, diagnostics, tyres, fork, dyno, ECU work | D33: https://www.cdmotorsport.my/perkhidmatan/ | E33: 2026 snapshot | F33: Medium | G33: Provider-specific | H33: Used to validate specialist service availability.
A35: Methodology Notes
A36: 1. Scope: Malaysia-first snapshot as of 18 Aug 2026, with global motorcycle type taxonomy adapted to local use cases.
A37: 2. “Current retail” is reserved for official Malaysia product/showroom evidence. “Website-listed” allows model-year carryovers. “Dealer-listed” is retail evidence but not a national inventory guarantee. “Support footprint” means parts/service evidence and can include legacy models.
A38: 3. Model counts should not be interpreted as sales share. A brand can list many low-volume models while another sells very high volumes through a few commuter models.
A39: 4. Registration figures are preferred from data.gov.my/JPJ. Third-party market estimates are kept in a separate evidence category.
A40: 5. Service landscape is organized by capability and customer trigger, because Malaysia has a fragmented mix of OEM dealers, neighbourhood workshops, specialist tuners, mobile providers, insurers/panel shops and emerging EV service partners.
A41: 6. Service intervals are not prescribed here. Always follow the specific owner/service manual for the motorcycle and riding conditions.
A42: 7. This workbook is a research database, not legal, warranty, safety or mechanical advice. Availability, prices, dealer authorization, policy benefits and model years should be verified before commercial use.
A44: Service Taxonomy source URLs are evidence/basis anchors for the service class; model-specific intervals, torque values, fluids and procedures must always follow the relevant OEM service manual.
